//! Error handling verification tests for unsafe patterns remediation

#[cfg(test)]
mod tests {
    use crate::{Result, WritemagicError};

    /// Test error propagation without panics
    #[tokio::test]
    async fn test_result_error_handling() {
        async fn fallible_operation() -> Result<String> {
            Err(WritemagicError::validation("Test error"))
        }

        let result = fallible_operation().await;
        assert!(result.is_err());
        
        // Ensure error can be propagated without unwrap
        let error_message = match result {
            Ok(_) => panic!("Expected error"),
            Err(e) => e.to_string(),
        };
        
        assert!(error_message.contains("Test error"));
    }

    /// Test graceful degradation
    #[test]
    fn test_graceful_fallback() {
        fn risky_operation() -> Result<i32> {
            Err(WritemagicError::internal("Simulated failure"))
        }
        
        let value = risky_operation().unwrap_or(42);
        assert_eq!(value, 42);
    }

    /// Test optional chaining for error recovery
    #[test]
    fn test_optional_chaining() {
        fn maybe_fail() -> Option<String> {
            None // Simulated failure
        }
        
        let result = maybe_fail()
            .or_else(|| Some("fallback".to_string()))
            .unwrap_or_else(|| "final_fallback".to_string());
            
        assert_eq!(result, "fallback");
    }

    /// Test error context preservation
    #[test]
    fn test_error_context() {
        fn operation_with_context() -> Result<()> {
            Err(WritemagicError::ai_provider("Provider failed"))
                .map_err(|e| WritemagicError::internal(format!("Operation failed: {}", e)))
        }
        
        let error = operation_with_context().unwrap_err();
        assert!(error.to_string().contains("Operation failed"));
        assert!(error.to_string().contains("Provider failed"));
    }

    /// Test async error propagation
    #[tokio::test]
    async fn test_async_error_propagation() {
        async fn async_operation() -> Result<String> {
            tokio::time::sleep(std::time::Duration::from_millis(1)).await;
            Err(WritemagicError::timeout(100))
        }
        
        async fn caller() -> Result<String> {
            let result = async_operation().await?;
            Ok(result)
        }
        
        let error = caller().await.unwrap_err();
        assert!(matches!(error, WritemagicError::Timeout { .. }));
    }
}